<?xml version="1.0"?>
<!-- Minimal generated SDF -->
<sdf version='1.6'>
  <model name='multiple_objects'>
    <link name='house_root'>
      <pose>0 0 0 0 0 0</pose>
    </link>

<!-- Beer bottle -->
   <link name="link_beer_bottle">
    <pose>0 0 0 0. 0.0 0.0</pose>
    <inertial>
      <pose frame="">0.0000e+00 0.0000e+00 8.3000e-02 0.0000e+00 0.0000e+00 0.0000e+00</pose>
      <mass>0.887</mass>
      <inertia>
        <ixx>0.003</ixx>
        <ixy>0</ixy>
        <ixz>0</ixz>
        <iyy>0.003</iyy>
        <iyz>0</iyz>
        <izz>0.001</izz>
      </inertia>
    </inertial>
    <visual name="link_beer_bottle">
      <pose frame="">0.0000e+00 0.0000e+00 0.0000e+00 0.0000e+00 0.0000e+00 0.0000e+00</pose>
      <geometry>
        <mesh>
          <uri>beer_bottle/meshes/link_beer_bottle.obj</uri>
          <scale>1.0000e+00 1.0000e+00 1.0000e+00</scale>
        </mesh>
      </geometry>
      <material>
        <drake:diffuse_map>beer_bottle/meshes/link_beer_bottle_Bake1_pbr_diffuse.png</drake:diffuse_map>
        <drake:normal_map>beer_bottle/meshes/link_beer_bottle_Bake1_pbr_normal.png</drake:normal_map>
        <drake:roughness_map>beer_bottle/meshes/link_beer_bottle_Bake1_pbr_roughness.png</drake:roughness_map>
        <drake:metalness_map>beer_bottle/meshes/link_beer_bottle_Bake1_pbr_metalness.png</drake:metalness_map>
        <drake:alpha_map>beer_bottle/meshes/link_beer_bottle_Bake1_pbr_alpha.png</drake:alpha_map>
      </material>
    </visual>
    <collision name="Cylinder">
      <pose frame="">0.0000e+00 0.0000e+00 0.0000e+00 0.0000e+00 0.0000e+00 0.0000e+00</pose>
      <geometry>
        <mesh>
          <uri>beer_bottle/meshes/Cylinder.obj</uri>
          <scale>1.0000e+00 1.0000e+00 1.0000e+00</scale>
          <drake:declare_convex/>
        </mesh>
      </geometry>
    </collision>
    <collision name="Cylinder.001">
      <pose frame="">0.0000e+00 0.0000e+00 0.0000e+00 0.0000e+00 0.0000e+00 0.0000e+00</pose>
      <geometry>
        <mesh>
          <uri>beer_bottle/meshes/Cylinder.001.obj</uri>
          <scale>1.0000e+00 1.0000e+00 1.0000e+00</scale>
          <drake:declare_convex/>
        </mesh>
      </geometry>
    </collision>
  </link>

  <joint name="house_root_to_bear_bottle" type="fixed">
    <child>link_beer_bottle</child>
    <parent>house_root</parent>
  </joint>

<!-- Cereal box -->
  <link name="link_cereal_box">
    <pose>0.2 0.2 0.2 0 0.0 0.0</pose>
    <inertial>
      <pose frame="">0.0000e+00 0.0000e+00 1.7200e-01 0.0000e+00 0.0000e+00 0.0000e+00</pose>
      <mass>0.719</mass>
      <inertia>
        <ixx>0.008</ixx>
        <ixy>0</ixy>
        <ixz>0</ixz>
        <iyy>0.011</iyy>
        <iyz>0</iyz>
        <izz>0.004</izz>
      </inertia>
    </inertial>
    <visual name="link_cereal_box">
      <pose frame="">0.0000e+00 0.0000e+00 0.0000e+00 0.0000e+00 0.0000e+00 0.0000e+00</pose>
      <geometry>
        <mesh>
          <uri>cereal_box/meshes/link_cereal_box.obj</uri>
          <scale>1.0000e+00 1.0000e+00 1.0000e+00</scale>
        </mesh>
      </geometry>
      <material>
        <drake:diffuse_map>cereal_box/meshes/link_cereal_box_Bake1_pbr_diffuse.png</drake:diffuse_map>
        <drake:specular_map>cereal_box/meshes/link_cereal_box_Bake1_pbr_specular.png</drake:specular_map>
        <drake:roughness_map>cereal_box/meshes/link_cereal_box_Bake1_pbr_roughness.png</drake:roughness_map>
      </material>
    </visual>
    <collision name="cereal_box_hull_1">
      <pose frame="">0.0000e+00 0.0000e+00 0.0000e+00 0.0000e+00 0.0000e+00 0.0000e+00</pose>
      <geometry>
        <mesh>
          <uri>cereal_box/meshes/cereal_box_hull_1.obj</uri>
          <scale>1.0000e+00 1.0000e+00 1.0000e+00</scale>
          <drake:declare_convex/>
        </mesh>
      </geometry>
    </collision>
  </link>

  <joint name="cereal_box_root_to_cereal_box" type="fixed">
    <child>link_cereal_box</child>
    <parent>house_root</parent>
  </joint>


<!-- Storage cabinet body -->
   <link name="link_storage_cabinet_body">
      <pose>1.0 1.0 1.0 0 0.0 0.0</pose>
      <inertial>
        <pose frame="">-7.0000e-03 6.1000e-02 9.4000e-01 0.0000e+00 0.0000e+00 0.0000e+00</pose>
        <mass>198.026</mass>
        <inertia>
          <ixx>92.421</ixx>
          <ixy>0</ixy>
          <ixz>0</ixz>
          <iyy>117.554</iyy>
          <iyz>0</iyz>
          <izz>39.481</izz>
        </inertia>
      </inertial>
      <visual name="link_storage_cabinet_body">
        <pose frame="">0.0000e+00 0.0000e+00 0.0000e+00 0.0000e+00 0.0000e+00 0.0000e+00</pose>
        <geometry>
          <mesh>
            <uri>storage_cabinet/meshes/link_storage_cabinet_body.obj</uri>
            <scale>1.0000e+00 1.0000e+00 1.0000e+00</scale>
          </mesh>
        </geometry>
        <material>
          <drake:diffuse_map>storage_cabinet/meshes/link_storage_cabinet_body_Bake1_pbr_diffuse.png</drake:diffuse_map>
          <drake:normal_map>storage_cabinet/meshes/link_storage_cabinet_body_Bake1_pbr_normal.png</drake:normal_map>
          <drake:specular_map>storage_cabinet/meshes/link_storage_cabinet_body_Bake1_pbr_specular.png</drake:specular_map>
          <drake:roughness_map>storage_cabinet/meshes/link_storage_cabinet_body_Bake1_pbr_roughness.png</drake:roughness_map>
          <drake:metalness_map>storage_cabinet/meshes/link_storage_cabinet_body_Bake1_pbr_metalness.png</drake:metalness_map>
        </material>
      </visual>
      <collision name="link_storage_cabinet_body.001_hull_1">
        <pose frame="">0.0000e+00 0.0000e+00 0.0000e+00 0.0000e+00 0.0000e+00 0.0000e+00</pose>
        <geometry>
          <mesh>
            <uri>storage_cabinet/meshes/link_storage_cabinet_body.001_hull_1.obj</uri>
            <scale>1.0000e+00 1.0000e+00 1.0000e+00</scale>
            <drake:declare_convex/>
          </mesh>
        </geometry>
      </collision>
      <collision name="link_storage_cabinet_body.001_hull_2">
        <pose frame="">0.0000e+00 0.0000e+00 0.0000e+00 0.0000e+00 0.0000e+00 0.0000e+00</pose>
        <geometry>
          <mesh>
            <uri>storage_cabinet/meshes/link_storage_cabinet_body.001_hull_2.obj</uri>
            <scale>1.0000e+00 1.0000e+00 1.0000e+00</scale>
            <drake:declare_convex/>
          </mesh>
        </geometry>
      </collision>
      <collision name="link_storage_cabinet_body.001_hull_3">
        <pose frame="">0.0000e+00 0.0000e+00 0.0000e+00 0.0000e+00 0.0000e+00 0.0000e+00</pose>
        <geometry>
          <mesh>
            <uri>storage_cabinet/meshes/link_storage_cabinet_body.001_hull_3.obj</uri>
            <scale>1.0000e+00 1.0000e+00 1.0000e+00</scale>
            <drake:declare_convex/>
          </mesh>
        </geometry>
      </collision>
      <collision name="link_storage_cabinet_body.001_hull_4">
        <pose frame="">0.0000e+00 0.0000e+00 0.0000e+00 0.0000e+00 0.0000e+00 0.0000e+00</pose>
        <geometry>
          <mesh>
            <uri>storage_cabinet/meshes/link_storage_cabinet_body.001_hull_4.obj</uri>
            <scale>1.0000e+00 1.0000e+00 1.0000e+00</scale>
            <drake:declare_convex/>
          </mesh>
        </geometry>
      </collision>
      <collision name="link_storage_cabinet_body.001_hull_5">
        <pose frame="">0.0000e+00 0.0000e+00 0.0000e+00 0.0000e+00 0.0000e+00 0.0000e+00</pose>
        <geometry>
          <mesh>
            <uri>storage_cabinet/meshes/link_storage_cabinet_body.001_hull_5.obj</uri>
            <scale>1.0000e+00 1.0000e+00 1.0000e+00</scale>
            <drake:declare_convex/>
          </mesh>
        </geometry>
      </collision>
      <collision name="link_storage_cabinet_body.001_hull_6">
        <pose frame="">0.0000e+00 0.0000e+00 0.0000e+00 0.0000e+00 0.0000e+00 0.0000e+00</pose>
        <geometry>
          <mesh>
            <uri>storage_cabinet/meshes/link_storage_cabinet_body.001_hull_6.obj</uri>
            <scale>1.0000e+00 1.0000e+00 1.0000e+00</scale>
            <drake:declare_convex/>
          </mesh>
        </geometry>
      </collision>
      <collision name="link_storage_cabinet_body.001_hull_7">
        <pose frame="">0.0000e+00 0.0000e+00 0.0000e+00 0.0000e+00 0.0000e+00 0.0000e+00</pose>
        <geometry>
          <mesh>
            <uri>storage_cabinet/meshes/link_storage_cabinet_body.001_hull_7.obj</uri>
            <scale>1.0000e+00 1.0000e+00 1.0000e+00</scale>
            <drake:declare_convex/>
          </mesh>
        </geometry>
      </collision>
      <collision name="link_storage_cabinet_body.002_hull_1">
        <pose frame="">0.0000e+00 0.0000e+00 0.0000e+00 0.0000e+00 0.0000e+00 0.0000e+00</pose>
        <geometry>
          <mesh>
            <uri>storage_cabinet/meshes/link_storage_cabinet_body.002_hull_1.obj</uri>
            <scale>1.0000e+00 1.0000e+00 1.0000e+00</scale>
            <drake:declare_convex/>
          </mesh>
        </geometry>
      </collision>
      <collision name="link_storage_cabinet_body.003_hull_1">
        <pose frame="">0.0000e+00 0.0000e+00 0.0000e+00 0.0000e+00 0.0000e+00 0.0000e+00</pose>
        <geometry>
          <mesh>
            <uri>storage_cabinet/meshes/link_storage_cabinet_body.003_hull_1.obj</uri>
            <scale>1.0000e+00 1.0000e+00 1.0000e+00</scale>
            <drake:declare_convex/>
          </mesh>
        </geometry>
      </collision>
      <collision name="link_storage_cabinet_body.004_hull_1">
        <pose frame="">0.0000e+00 0.0000e+00 0.0000e+00 0.0000e+00 0.0000e+00 0.0000e+00</pose>
        <geometry>
          <mesh>
            <uri>storage_cabinet/meshes/link_storage_cabinet_body.004_hull_1.obj</uri>
            <scale>1.0000e+00 1.0000e+00 1.0000e+00</scale>
            <drake:declare_convex/>
          </mesh>
        </geometry>
      </collision>
      <collision name="link_storage_cabinet_body.005_hull_1">
        <pose frame="">0.0000e+00 0.0000e+00 0.0000e+00 0.0000e+00 0.0000e+00 0.0000e+00</pose>
        <geometry>
          <mesh>
            <uri>storage_cabinet/meshes/link_storage_cabinet_body.005_hull_1.obj</uri>
            <scale>1.0000e+00 1.0000e+00 1.0000e+00</scale>
            <drake:declare_convex/>
          </mesh>
        </geometry>
      </collision>
      <collision name="link_storage_cabinet_body.006_hull_1">
        <pose frame="">0.0000e+00 0.0000e+00 0.0000e+00 0.0000e+00 0.0000e+00 0.0000e+00</pose>
        <geometry>
          <mesh>
            <uri>storage_cabinet/meshes/link_storage_cabinet_body.006_hull_1.obj</uri>
            <scale>1.0000e+00 1.0000e+00 1.0000e+00</scale>
            <drake:declare_convex/>
          </mesh>
        </geometry>
      </collision>
      <collision name="link_storage_cabinet_body.007_hull_1">
        <pose frame="">0.0000e+00 0.0000e+00 0.0000e+00 0.0000e+00 0.0000e+00 0.0000e+00</pose>
        <geometry>
          <mesh>
            <uri>storage_cabinet/meshes/link_storage_cabinet_body.007_hull_1.obj</uri>
            <scale>1.0000e+00 1.0000e+00 1.0000e+00</scale>
            <drake:declare_convex/>
          </mesh>
        </geometry>
      </collision>
      <collision name="link_storage_cabinet_body.008_hull_1">
        <pose frame="">0.0000e+00 0.0000e+00 0.0000e+00 0.0000e+00 0.0000e+00 0.0000e+00</pose>
        <geometry>
          <mesh>
            <uri>storage_cabinet/meshes/link_storage_cabinet_body.008_hull_1.obj</uri>
            <scale>1.0000e+00 1.0000e+00 1.0000e+00</scale>
            <drake:declare_convex/>
          </mesh>
        </geometry>
      </collision>
    </link>
    <link name="link_storage_cabinet_door_L">
      <pose>1.0 1.0 1.0 0 0.0 0.0</pose>
      <inertial>
        <pose frame="">3.2400e-01 -3.1100e-01 9.3400e-01 0.0000e+00 0.0000e+00 0.0000e+00</pose>
        <mass>15.273</mass>
        <inertia>
          <ixx>3.683</ixx>
          <ixy>0</ixy>
          <ixz>0</ixz>
          <iyy>4.186</iyy>
          <iyz>0</iyz>
          <izz>0.506</izz>
        </inertia>
      </inertial>
      <visual name="link_storage_cabinet_door_L">
        <pose frame="">0.0000e+00 0.0000e+00 0.0000e+00 0.0000e+00 0.0000e+00 0.0000e+00</pose>
        <geometry>
          <mesh>
            <uri>storage_cabinet/meshes/link_storage_cabinet_door_L.obj</uri>
            <scale>1.0000e+00 1.0000e+00 1.0000e+00</scale>
          </mesh>
        </geometry>
        <material>
          <drake:diffuse_map>storage_cabinet/meshes/link_storage_cabinet_door_L_Bake1_pbr_diffuse.png</drake:diffuse_map>
          <drake:normal_map>storage_cabinet/meshes/link_storage_cabinet_door_L_Bake1_pbr_normal.png</drake:normal_map>
          <drake:specular_map>storage_cabinet/meshes/link_storage_cabinet_door_L_Bake1_pbr_specular.png</drake:specular_map>
          <drake:roughness_map>storage_cabinet/meshes/link_storage_cabinet_door_L_Bake1_pbr_roughness.png</drake:roughness_map>
          <drake:metalness_map>storage_cabinet/meshes/link_storage_cabinet_door_L_Bake1_pbr_metalness.png</drake:metalness_map>
        </material>
      </visual>
      <collision name="Cube">
        <pose frame="">0.0000e+00 0.0000e+00 0.0000e+00 0.0000e+00 0.0000e+00 0.0000e+00</pose>
        <geometry>
          <mesh>
            <uri>storage_cabinet/meshes/Cube.obj</uri>
            <scale>1.0000e+00 1.0000e+00 1.0000e+00</scale>
            <drake:declare_convex/>
          </mesh>
        </geometry>
      </collision>
      <collision name="Cube.001">
        <pose frame="">0.0000e+00 0.0000e+00 0.0000e+00 0.0000e+00 0.0000e+00 0.0000e+00</pose>
        <geometry>
          <mesh>
            <uri>storage_cabinet/meshes/Cube.001.obj</uri>
            <scale>1.0000e+00 1.0000e+00 1.0000e+00</scale>
            <drake:declare_convex/>
          </mesh>
        </geometry>
      </collision>
      <collision name="Cube.002">
        <pose frame="">0.0000e+00 0.0000e+00 0.0000e+00 0.0000e+00 0.0000e+00 0.0000e+00</pose>
        <geometry>
          <mesh>
            <uri>storage_cabinet/meshes/Cube.002.obj</uri>
            <scale>1.0000e+00 1.0000e+00 1.0000e+00</scale>
            <drake:declare_convex/>
          </mesh>
        </geometry>
      </collision>
      <collision name="link_storage_cabinet_door_L.001_hull_1">
        <pose frame="">0.0000e+00 0.0000e+00 0.0000e+00 0.0000e+00 0.0000e+00 0.0000e+00</pose>
        <geometry>
          <mesh>
            <uri>storage_cabinet/meshes/link_storage_cabinet_door_L.001_hull_1.obj</uri>
            <scale>1.0000e+00 1.0000e+00 1.0000e+00</scale>
            <drake:declare_convex/>
          </mesh>
        </geometry>
      </collision>
    </link>
    <link name="link_storage_cabinet_door_R">
      <pose>1.0 1.0 1.0 0 0.0 0.0</pose>
      <inertial>
        <pose frame="">-3.2400e-01 -3.1100e-01 9.3400e-01 0.0000e+00 0.0000e+00 0.0000e+00</pose>
        <mass>15.276</mass>
        <inertia>
          <ixx>3.684</ixx>
          <ixy>0</ixy>
          <ixz>0</ixz>
          <iyy>4.188</iyy>
          <iyz>0</iyz>
          <izz>0.506</izz>
        </inertia>
      </inertial>
      <visual name="link_storage_cabinet_door_R">
        <pose frame="">0.0000e+00 0.0000e+00 0.0000e+00 0.0000e+00 0.0000e+00 0.0000e+00</pose>
        <geometry>
          <mesh>
            <uri>storage_cabinet/meshes/link_storage_cabinet_door_R.obj</uri>
            <scale>1.0000e+00 1.0000e+00 1.0000e+00</scale>
          </mesh>
        </geometry>
        <material>
          <drake:diffuse_map>storage_cabinet/meshes/link_storage_cabinet_door_R_Bake1_pbr_diffuse.png</drake:diffuse_map>
          <drake:normal_map>storage_cabinet/meshes/link_storage_cabinet_door_R_Bake1_pbr_normal.png</drake:normal_map>
          <drake:specular_map>storage_cabinet/meshes/link_storage_cabinet_door_R_Bake1_pbr_specular.png</drake:specular_map>
          <drake:roughness_map>storage_cabinet/meshes/link_storage_cabinet_door_R_Bake1_pbr_roughness.png</drake:roughness_map>
          <drake:metalness_map>storage_cabinet/meshes/link_storage_cabinet_door_R_Bake1_pbr_metalness.png</drake:metalness_map>
        </material>
      </visual>
      <collision name="Cube.003">
        <pose frame="">0.0000e+00 0.0000e+00 0.0000e+00 0.0000e+00 0.0000e+00 0.0000e+00</pose>
        <geometry>
          <mesh>
            <uri>storage_cabinet/meshes/Cube.003.obj</uri>
            <scale>1.0000e+00 1.0000e+00 1.0000e+00</scale>
            <drake:declare_convex/>
          </mesh>
        </geometry>
      </collision>
      <collision name="Cube.004">
        <pose frame="">0.0000e+00 0.0000e+00 0.0000e+00 0.0000e+00 0.0000e+00 0.0000e+00</pose>
        <geometry>
          <mesh>
            <uri>storage_cabinet/meshes/Cube.004.obj</uri>
            <scale>1.0000e+00 1.0000e+00 1.0000e+00</scale>
            <drake:declare_convex/>
          </mesh>
        </geometry>
      </collision>
      <collision name="Cube.005">
        <pose frame="">0.0000e+00 0.0000e+00 0.0000e+00 0.0000e+00 0.0000e+00 0.0000e+00</pose>
        <geometry>
          <mesh>
            <uri>storage_cabinet/meshes/Cube.005.obj</uri>
            <scale>1.0000e+00 1.0000e+00 1.0000e+00</scale>
            <drake:declare_convex/>
          </mesh>
        </geometry>
      </collision>
      <collision name="link_storage_cabinet_door_R.001_hull_1">
        <pose frame="">0.0000e+00 0.0000e+00 0.0000e+00 0.0000e+00 0.0000e+00 0.0000e+00</pose>
        <geometry>
          <mesh>
            <uri>storage_cabinet/meshes/link_storage_cabinet_door_R.001_hull_1.obj</uri>
            <scale>1.0000e+00 1.0000e+00 1.0000e+00</scale>
            <drake:declare_convex/>
          </mesh>
        </geometry>
      </collision>
    </link>
    <joint name="link_storage_cabinet_body_link_storage_cabinet_door_L" type="revolute">
      <child>link_storage_cabinet_door_L</child>
      <parent>link_storage_cabinet_body</parent>
      <pose frame="">6.4861e-01 -2.9715e-01 9.5511e-01 0.0000e+00 -0.0000e+00 0.0000e+00</pose>
      <axis>
        <xyz>0.0 0.0 1.0</xyz>
        <limit>
          <effort>0</effort>
          <lower>0.0</lower>
          <upper>1.832595705986023</upper>
        </limit>
        <dynamics>
          <damping>1.0</damping>
        </dynamics>
        <use_parent_model_frame>1</use_parent_model_frame>
      </axis>
    </joint>
    <joint name="link_storage_cabinet_body_link_storage_cabinet_door_R" type="revolute">
      <child>link_storage_cabinet_door_R</child>
      <parent>link_storage_cabinet_body</parent>
      <pose frame="">-6.4853e-01 -2.9713e-01 9.5511e-01 0.0000e+00 -0.0000e+00 0.0000e+00</pose>
      <axis>
        <xyz>0.0 0.0 1.0</xyz>
        <limit>
          <effort>0</effort>
          <lower>-1.832595705986023</lower>
          <upper>0.0</upper>
        </limit>
        <dynamics>
          <damping>1.0</damping>
        </dynamics>
        <use_parent_model_frame>1</use_parent_model_frame>
      </axis>
    </joint>

    <joint name="house_root_to_storage_cabinet" type="fixed">
    <child>link_storage_cabinet_body</child>
    <parent>house_root</parent>
  </joint>
  </model>
</sdf>
